<?xml version="1.0" ?>
<!-- =================================================================================== -->
<!-- |    This document was autogenerated by xacro from car_union.urdf.xacro           | -->
<!-- |    EDITING THIS FILE BY HAND IS NOT RECOMMENDED                                 | -->
<!-- =================================================================================== -->
<robot name="mycar">
  <material name="black">
    <color rgba="0.0 0.0 0.0 1.0"/>
  </material>
  <!--Temp Useless-->
  &gt;
    
  <!-- 0.58 -->
  &gt;
    
  <link name="base_footprint">
    <visual>
      <geometry>
        <sphere radius="0.001"/>
      </geometry>
    </visual>
  </link>
  <link name="base_link">
    <visual>
      <geometry>
        <!-- <cylinder radius="${base_link_radius}" length="${base_link_length}" /> -->
        <box size="0.25 0.25 0.04"/>
      </geometry>
      <origin rpy="0 0 0" xyz="0 0 0"/>
      <material name="yellow">
        <color rgba="0.5 0.3 0.0 0.5"/>
      </material>
    </visual>
    <collision>
      <geometry>
        <box size="0.25 0.25 0.04"/>
      </geometry>
      <origin rpy="0 0 0" xyz="0 0 0"/>
    </collision>
    <inertial>
      <mass value="0.3"/>
      <inertia ixx="0.0016025" ixy="0" ixz="0" iyy="0.0031249999999999997" iyz="0" izz="0.0016025"/>
    </inertial>
  </link>
  <joint name="base_link2base_footprint" type="fixed">
    <parent link="base_footprint"/>
    <child link="base_link"/>
    <origin xyz="0 0 0.035"/>
  </joint>
  <gazebo reference="base_link">
    <material>Gazebo/Yellow</material>
  </gazebo>
  <link name="left_front_connect_link">
    <visual>
      <geometry>
        <cylinder length="0.04" radius="0.01"/>
      </geometry>
      <origin rpy="1.5707963 0.0 0.0" xyz="0.0 0.0 0.0"/>
      <!-- show color for rviz -->
      <material name="black"/>
    </visual>
    <collision>
      <geometry>
        <cylinder length="0.04" radius="0.01"/>
      </geometry>
      <origin rpy="1.5707963 0.0 0.0" xyz="0.0 0.0 0.0"/>
    </collision>
    <inertial>
      <mass value="0.016666666666666666"/>
      <inertia ixx="2.638888888888889e-06" ixy="0" ixz="0" iyy="2.638888888888889e-06" iyz="0" izz="8.333333333333333e-07"/>
    </inertial>
  </link>
  <joint name="left_front_connect2wheel" type="fixed">
    <parent link="base_link"/>
    <child link="left_front_connect_link"/>
    <origin xyz="0.1 0.125 -0.0025000000000000022"/>
    <axis xyz="0 1 0"/>
  </joint>
  <!--only add next statement ,gazebo can show the color-->
  <gazebo reference="left_front_connect_link">
    <material>Gazebo/Black</material>
  </gazebo>
  <link name="left_rear_connect_link">
    <visual>
      <geometry>
        <cylinder length="0.04" radius="0.01"/>
      </geometry>
      <origin rpy="1.5707963 0.0 0.0" xyz="0.0 0.0 0.0"/>
      <!-- show color for rviz -->
      <material name="black"/>
    </visual>
    <collision>
      <geometry>
        <cylinder length="0.04" radius="0.01"/>
      </geometry>
      <origin rpy="1.5707963 0.0 0.0" xyz="0.0 0.0 0.0"/>
    </collision>
    <inertial>
      <mass value="0.016666666666666666"/>
      <inertia ixx="2.638888888888889e-06" ixy="0" ixz="0" iyy="2.638888888888889e-06" iyz="0" izz="8.333333333333333e-07"/>
    </inertial>
  </link>
  <joint name="left_rear_connect2wheel" type="fixed">
    <parent link="base_link"/>
    <child link="left_rear_connect_link"/>
    <origin xyz="-0.1 0.125 -0.0025000000000000022"/>
    <axis xyz="0 1 0"/>
  </joint>
  <!--only add next statement ,gazebo can show the color-->
  <gazebo reference="left_rear_connect_link">
    <material>Gazebo/Black</material>
  </gazebo>
  <link name="right_front_connect_link">
    <visual>
      <geometry>
        <cylinder length="0.04" radius="0.01"/>
      </geometry>
      <origin rpy="1.5707963 0.0 0.0" xyz="0.0 0.0 0.0"/>
      <!-- show color for rviz -->
      <material name="black"/>
    </visual>
    <collision>
      <geometry>
        <cylinder length="0.04" radius="0.01"/>
      </geometry>
      <origin rpy="1.5707963 0.0 0.0" xyz="0.0 0.0 0.0"/>
    </collision>
    <inertial>
      <mass value="0.016666666666666666"/>
      <inertia ixx="2.638888888888889e-06" ixy="0" ixz="0" iyy="2.638888888888889e-06" iyz="0" izz="8.333333333333333e-07"/>
    </inertial>
  </link>
  <joint name="right_front_connect2wheel" type="fixed">
    <parent link="base_link"/>
    <child link="right_front_connect_link"/>
    <origin xyz="0.1 -0.125 -0.0025000000000000022"/>
    <axis xyz="0 1 0"/>
  </joint>
  <!--only add next statement ,gazebo can show the color-->
  <gazebo reference="right_front_connect_link">
    <material>Gazebo/Black</material>
  </gazebo>
  <link name="right_rear_connect_link">
    <visual>
      <geometry>
        <cylinder length="0.04" radius="0.01"/>
      </geometry>
      <origin rpy="1.5707963 0.0 0.0" xyz="0.0 0.0 0.0"/>
      <!-- show color for rviz -->
      <material name="black"/>
    </visual>
    <collision>
      <geometry>
        <cylinder length="0.04" radius="0.01"/>
      </geometry>
      <origin rpy="1.5707963 0.0 0.0" xyz="0.0 0.0 0.0"/>
    </collision>
    <inertial>
      <mass value="0.016666666666666666"/>
      <inertia ixx="2.638888888888889e-06" ixy="0" ixz="0" iyy="2.638888888888889e-06" iyz="0" izz="8.333333333333333e-07"/>
    </inertial>
  </link>
  <joint name="right_rear_connect2wheel" type="fixed">
    <parent link="base_link"/>
    <child link="right_rear_connect_link"/>
    <origin xyz="-0.1 -0.125 -0.0025000000000000022"/>
    <axis xyz="0 1 0"/>
  </joint>
  <!--only add next statement ,gazebo can show the color-->
  <gazebo reference="right_rear_connect_link">
    <material>Gazebo/Black</material>
  </gazebo>
  <link name="left_front_wheel">
    <visual>
      <geometry>
        <cylinder length="0.035" radius="0.0325"/>
      </geometry>
      <origin rpy="1.5707963 0.0 0.0" xyz="0.0 0.0 0.0"/>
      <material name="black"/>
    </visual>
    <collision>
      <geometry>
        <cylinder length="0.035" radius="0.0325"/>
      </geometry>
      <origin rpy="1.5707963 0.0 0.0" xyz="0.0 0.0 0.0"/>
    </collision>
    <inertial>
      <mass value="0.05"/>
      <inertia ixx="1.830729166666667e-05" ixy="0" ixz="0" iyy="1.830729166666667e-05" iyz="0" izz="2.6406250000000005e-05"/>
    </inertial>
  </link>
  <joint name="left_front_wheel2base_link" type="continuous">
    <parent link="left_front_connect_link"/>
    <child link="left_front_wheel"/>
    <origin xyz="0 0.02 -0.0025000000000000022"/>
    <axis xyz="0 1 0"/>
  </joint>
  <gazebo reference="left_front_wheel">
    <material>Gazebo/Red</material>
  </gazebo>
  <link name="left_rear_wheel">
    <visual>
      <geometry>
        <cylinder length="0.035" radius="0.0325"/>
      </geometry>
      <origin rpy="1.5707963 0.0 0.0" xyz="0.0 0.0 0.0"/>
      <material name="black"/>
    </visual>
    <collision>
      <geometry>
        <cylinder length="0.035" radius="0.0325"/>
      </geometry>
      <origin rpy="1.5707963 0.0 0.0" xyz="0.0 0.0 0.0"/>
    </collision>
    <inertial>
      <mass value="0.05"/>
      <inertia ixx="1.830729166666667e-05" ixy="0" ixz="0" iyy="1.830729166666667e-05" iyz="0" izz="2.6406250000000005e-05"/>
    </inertial>
  </link>
  <joint name="left_rear_wheel2base_link" type="continuous">
    <parent link="left_rear_connect_link"/>
    <child link="left_rear_wheel"/>
    <origin xyz="0 0.02 -0.0025000000000000022"/>
    <axis xyz="0 1 0"/>
  </joint>
  <gazebo reference="left_rear_wheel">
    <material>Gazebo/Red</material>
  </gazebo>
  <link name="right_front_wheel">
    <visual>
      <geometry>
        <cylinder length="0.035" radius="0.0325"/>
      </geometry>
      <origin rpy="1.5707963 0.0 0.0" xyz="0.0 0.0 0.0"/>
      <material name="black"/>
    </visual>
    <collision>
      <geometry>
        <cylinder length="0.035" radius="0.0325"/>
      </geometry>
      <origin rpy="1.5707963 0.0 0.0" xyz="0.0 0.0 0.0"/>
    </collision>
    <inertial>
      <mass value="0.05"/>
      <inertia ixx="1.830729166666667e-05" ixy="0" ixz="0" iyy="1.830729166666667e-05" iyz="0" izz="2.6406250000000005e-05"/>
    </inertial>
  </link>
  <joint name="right_front_wheel2base_link" type="continuous">
    <parent link="right_front_connect_link"/>
    <child link="right_front_wheel"/>
    <origin xyz="0 -0.02 -0.0025000000000000022"/>
    <axis xyz="0 1 0"/>
  </joint>
  <gazebo reference="right_front_wheel">
    <material>Gazebo/Red</material>
  </gazebo>
  <link name="right_rear_wheel">
    <visual>
      <geometry>
        <cylinder length="0.035" radius="0.0325"/>
      </geometry>
      <origin rpy="1.5707963 0.0 0.0" xyz="0.0 0.0 0.0"/>
      <material name="black"/>
    </visual>
    <collision>
      <geometry>
        <cylinder length="0.035" radius="0.0325"/>
      </geometry>
      <origin rpy="1.5707963 0.0 0.0" xyz="0.0 0.0 0.0"/>
    </collision>
    <inertial>
      <mass value="0.05"/>
      <inertia ixx="1.830729166666667e-05" ixy="0" ixz="0" iyy="1.830729166666667e-05" iyz="0" izz="2.6406250000000005e-05"/>
    </inertial>
  </link>
  <joint name="right_rear_wheel2base_link" type="continuous">
    <parent link="right_rear_connect_link"/>
    <child link="right_rear_wheel"/>
    <origin xyz="0 -0.02 -0.0025000000000000022"/>
    <axis xyz="0 1 0"/>
  </joint>
  <gazebo reference="right_rear_wheel">
    <material>Gazebo/Red</material>
  </gazebo>
  <!-- <xacro:add_support_wheel name="front" flag="1" />
    <xacro:add_support_wheel name="back" flag="-1" /> -->
  <link name="camera">
    <visual>
      <geometry>
        <box size="0.01 0.025 0.025"/>
      </geometry>
      <origin rpy="0.0 0.0 0.0" xyz="0.0 0.0 0.0"/>
      <material name="black"/>
    </visual>
    <collision>
      <geometry>
        <box size="0.01 0.025 0.025"/>
      </geometry>
      <origin rpy="0.0 0.0 0.0" xyz="0.0 0.0 0.0"/>
    </collision>
    <inertial>
      <mass value="0.01"/>
      <inertia ixx="6.041666666666668e-07" ixy="0" ixz="0" iyy="6.041666666666668e-07" iyz="0" izz="1.041666666666667e-06"/>
    </inertial>
  </link>
  <joint name="camera2base_link" type="fixed">
    <parent link="base_link"/>
    <child link="camera"/>
    <origin xyz="0.08 0.0 0.0325"/>
  </joint>
  <gazebo reference="camera">
    <material>Gazebo/Blue</material>
  </gazebo>
  <link name="support">
    <visual>
      <geometry>
        <cylinder length="0.05" radius="0.01"/>
      </geometry>
      <origin rpy="0.0 0.0 0.0" xyz="0.0 0.0 0.0"/>
      <material name="red">
        <color rgba="0.8 0.2 0.0 0.8"/>
      </material>
    </visual>
    <collision>
      <geometry>
        <cylinder length="0.05" radius="0.01"/>
      </geometry>
      <origin rpy="0.0 0.0 0.0" xyz="0.0 0.0 0.0"/>
    </collision>
    <inertial>
      <mass value="0.02"/>
      <inertia ixx="4.666666666666667e-06" ixy="0" ixz="0" iyy="4.666666666666667e-06" iyz="0" izz="1.0000000000000002e-06"/>
    </inertial>
  </link>
  <joint name="support2base_link" type="fixed">
    <parent link="base_link"/>
    <child link="support"/>
    <origin xyz="0.0 0.0 0.045"/>
  </joint>
  <gazebo reference="support">
    <material>Gazebo/White</material>
  </gazebo>
  <link name="laser">
    <visual>
      <geometry>
        <cylinder length="0.05" radius="0.03"/>
      </geometry>
      <origin rpy="0.0 0.0 0.0" xyz="0.0 0.0 0.0"/>
      <material name="black"/>
    </visual>
    <collision>
      <geometry>
        <cylinder length="0.05" radius="0.03"/>
      </geometry>
      <origin rpy="0.0 0.0 0.0" xyz="0.0 0.0 0.0"/>
    </collision>
    <inertial>
      <mass value="0.1"/>
      <inertia ixx="4.333333333333333e-05" ixy="0" ixz="0" iyy="4.333333333333333e-05" iyz="0" izz="4.4999999999999996e-05"/>
    </inertial>
  </link>
  <joint name="laser2support" type="fixed">
    <parent link="support"/>
    <child link="laser"/>
    <origin xyz="0.0 0.0 0.05"/>
  </joint>
  <gazebo reference="laser">
    <material>Gazebo/Black</material>
  </gazebo>
  <!-- Transmission is important to link the joints and the controller -->
  <transmission name="left_front_wheel2base_link_trans">
    <type>transmission_interface/SimpleTransmission</type>
    <joint name="left_front_wheel2base_link">
      <hardwareInterface>hardware_interface/VelocityJointInterface</hardwareInterface>
    </joint>
    <actuator name="left_front_wheel2base_link_motor">
      <hardwareInterface>hardware_interface/VelocityJointInterface</hardwareInterface>
      <mechanicalReduction>1</mechanicalReduction>
    </actuator>
  </transmission>
  <!-- Transmission is important to link the joints and the controller -->
  <transmission name="right_front_wheel2base_link_trans">
    <type>transmission_interface/SimpleTransmission</type>
    <joint name="right_front_wheel2base_link">
      <hardwareInterface>hardware_interface/VelocityJointInterface</hardwareInterface>
    </joint>
    <actuator name="right_front_wheel2base_link_motor">
      <hardwareInterface>hardware_interface/VelocityJointInterface</hardwareInterface>
      <mechanicalReduction>1</mechanicalReduction>
    </actuator>
  </transmission>
  <!-- Transmission is important to link the joints and the controller -->
  <transmission name="left_rear_wheel2base_link_trans">
    <type>transmission_interface/SimpleTransmission</type>
    <joint name="left_rear_wheel2base_link">
      <hardwareInterface>hardware_interface/VelocityJointInterface</hardwareInterface>
    </joint>
    <actuator name="left_rear_wheel2base_link_motor">
      <hardwareInterface>hardware_interface/VelocityJointInterface</hardwareInterface>
      <mechanicalReduction>1</mechanicalReduction>
    </actuator>
  </transmission>
  <!-- Transmission is important to link the joints and the controller -->
  <transmission name="right_rear_wheel2base_link_trans">
    <type>transmission_interface/SimpleTransmission</type>
    <joint name="right_rear_wheel2base_link">
      <hardwareInterface>hardware_interface/VelocityJointInterface</hardwareInterface>
    </joint>
    <actuator name="right_rear_wheel2base_link_motor">
      <hardwareInterface>hardware_interface/VelocityJointInterface</hardwareInterface>
      <mechanicalReduction>1</mechanicalReduction>
    </actuator>
  </transmission>
  <gazebo>
    <plugin filename="libgazebo_ros_planar_move.so" name="mecanum_controller">
      <alwaysOn>true</alwaysOn>
      <updateRate>100.0</updateRate>
      <robotNamespace>/</robotNamespace>
      <leftFrontJoint>left_front_wheel2base_link</leftFrontJoint>
      <rightFrontJoint>right_front_wheel2base_link</rightFrontJoint>
      <leftRearJoint>left_rear_wheel2base_link</leftRearJoint>
      <rightRearJoint>right_rear_wheel2base_link</rightRearJoint>
      <wheelSeparation>0.25</wheelSeparation>
      <wheelDiameter>0.065</wheelDiameter>
      <torque>2</torque>
      <commandTopic>cmd_vel</commandTopic>
      <odometryTopic>odom</odometryTopic>
      <odometryFrame>odom</odometryFrame>
      <robotBaseFrame>base_footprint</robotBaseFrame>
      <broadcastTF>1</broadcastTF>
    </plugin>
  </gazebo>
  <gazebo reference="laser">
    <sensor name="rplidar" type="ray">
      <pose>0 0 0 0 0 0</pose>
      <visualize>true</visualize>
      <update_rate>5.5</update_rate>
      <ray>
        <scan>
          <horizontal>
            <samples>360</samples>
            <resolution>1</resolution>
            <min_angle>-3</min_angle>
            <max_angle>3</max_angle>
          </horizontal>
        </scan>
        <range>
          <min>0.10</min>
          <max>30.0</max>
          <resolution>0.01</resolution>
        </range>
        <noise>
          <type>gaussian</type>
          <mean>0.0</mean>
          <stddev>0.01</stddev>
        </noise>
      </ray>
      <plugin filename="libgazebo_ros_laser.so" name="gazebo_rplidar">
        <topicName>/scan</topicName>
        <frameName>laser</frameName>
      </plugin>
    </sensor>
  </gazebo>
  <gazebo reference="camera">
    <sensor name="camera_node" type="camera">
      <update_rate>30.0</update_rate>
      <camera name="head">
        <horizontal_fov>1.3962634</horizontal_fov>
        <image>
          <width>1280</width>
          <height>720</height>
          <format>R8G8B8</format>
        </image>
        <clip>
          <near>0.02</near>
          <far>300</far>
        </clip>
        <noise>
          <type>gaussian</type>
          <mean>0.0</mean>
          <stddev>0.007</stddev>
        </noise>
      </camera>
      <plugin filename="libgazebo_ros_camera.so" name="gazebo_camera">
        <alwaysOn>true</alwaysOn>
        <updateRate>0.0</updateRate>
        <cameraName>/camera</cameraName>
        <imageTopicName>image_raw</imageTopicName>
        <cameraInfoTopicName>camera_info</cameraInfoTopicName>
        <frameName>camera</frameName>
        <hackBaseline>0.07</hackBaseline>
        <distortionK1>0.0</distortionK1>
        <distortionK2>0.0</distortionK2>
        <distortionK3>0.0</distortionK3>
        <distortionT1>0.0</distortionT1>
        <distortionT2>0.0</distortionT2>
      </plugin>
    </sensor>
  </gazebo>
  <!-- <xacro:include filename="gazebo/kinect.xacro" /> -->
</robot>

